<?xml version="1.0"?>
<robot name="mbot" xmlns:xacro="http://www.ros.org/wiki/xacro">

    <!--
                                                                                     wheel_right_position                                               
                wheel_front_position                               body_position                          wheel_rear_position
                                                                                     wheel_left_position                                                 
    -->

    <!-- PROPERTY LIST -->
    <xacro:property name="M_PI" value="3.14159265354"/>

    <!-- body -->
    <xacro:property name="body_mass"   value="10" />
    <xacro:property name="body_h"            value="0.3"/>
    <xacro:property name="body_w"            value="0.85"/>
    <xacro:property name="body_l"              value="0.8"/>

    <!-- wheel_front -->
    <xacro:property name="wheel_front_mass"   value="1" />
    <xacro:property name="wheel_front_radius" value="0.125"/>
    <xacro:property name="wheel_front_x"            value="-0.3" />
    <xacro:property name="wheel_front_y"            value="0"/>
    <xacro:property name="wheel_front_z"             value="-0.1625"/>

     <!-- wheel_rear--> 
    <xacro:property name="wheel_rear_mass"   value="1" />
    <xacro:property name="wheel_rear_radius" value="0.125"/>
    <xacro:property name="wheel_rear_x"            value="0.3" />
    <xacro:property name="wheel_rear_y"            value="0"/>
    <xacro:property name="wheel_rear_z"             value="-0.1625"/>

    <!-- wheel_left -->
    <xacro:property name="wheel_left_mass"   value="3" />
    <xacro:property name="wheel_left_radius" value="0.125"/>
    <xacro:property name="wheel_left_h"           value="0.06"/>
    <xacro:property name="wheel_left_x"            value="0" />
    <xacro:property name="wheel_left_y"            value="-0.38"/>
    <xacro:property name="wheel_left_z"             value="-0.1"/>

    <!-- wheel_right -->
    <xacro:property name="wheel_right_mass"   value="3" />
    <xacro:property name="wheel_right_radius" value="0.125"/>
    <xacro:property name="wheel_right_h"           value="0.06"/>
    <xacro:property name="wheel_right_x"            value="0" />
    <xacro:property name="wheel_right_y"            value="0.38"/>
    <xacro:property name="wheel_right_z"             value="-0.1"/>

    <xacro:property name="wheel_Separation"         value="0.76"/>
    <xacro:property name="wheel_diameter"             value="0.25"/>


    <!-- Defining the colors used in this robot -->
    <material name="yellow">
        <color rgba="1 0.4 0 1"/>
    </material>
    <material name="black">
        <color rgba="0 0 0 0.95"/>
    </material>
    <material name="gray">
        <color rgba="0.75 0.75 0.75 1"/>
    </material>
    <material name="white">
        <color rgba="1 1 1 1"/>
    </material>
    <material name="orange">
        <color rgba="1 0.27 0 1"/>
    </material>
    
    <!-- Macro for inertia matrix -->
    <xacro:macro name="box_inertial_matrix" params="m l w h">
        <inertial>
            <mass value="${m}" />
            <inertia ixx="${m*(h*h + l*l)/12}" ixy = "0" ixz = "0"
                iyy="${m*(w*w + l*l)/12}" iyz= "0"
                izz="${m*(w*w + h*h)/12}" />
        </inertial>
    </xacro:macro>

    <xacro:macro name="sphere_inertial_matrix" params="m r">
        <inertial>
            <mass value="${m}" />
            <inertia ixx="${2*m*r*r/5}" ixy="0" ixz="0"
                iyy="${2*m*r*r/5}" iyz="0" 
                izz="${2*m*r*r/5}" />
        </inertial>
    </xacro:macro>

    <xacro:macro name="cylinder_inertial_matrix" params="m r h">
        <inertial>
            <mass value="${m}" />
            <inertia ixx="${m*(3*r*r+h*h)/12}" ixy = "0" ixz = "0"
                iyy="${m*(3*r*r+h*h)/12}" iyz = "0"
                izz="${m*r*r/2}" /> 
        </inertial>
    </xacro:macro>

    <xacro:macro name="kobuki">
        <link name="base_footprint"/>
            <joint name="base_joint" type="fixed">
            <origin xyz="0 0 0.0102" rpy="0 0 0" />
            <parent link="base_footprint"/>
            <child link="base_link" />
        </joint>
        <link name="base_link">
            <visual>
                <geometry>
                <!-- new mesh -->
                    <mesh filename="$(find kobuki_gazebo)/meshes/kobuki_robot/meshes/main_body.dae"/>
                </geometry>
                <origin xyz="0.001 0 0.05199" rpy="0 0 0"/>
            </visual>
            <collision name="base">
                <geometry>
                <cylinder length="0.10938" radius="0.178"/>
                </geometry>
                <origin xyz="0.0 0 0.05949" rpy="0 0 0"/>
            </collision>
            <inertial>
                <!-- COM experimentally determined -->
                <origin xyz="0.01 0 0"/>
                <mass value="2.4"/> <!-- 2.4/2.6 kg for small/big battery pack -->
                <inertia ixx="0.019995" ixy="0.0" ixz="0.0"
                        iyy="0.019995" iyz="0.0"
                        izz="0.03675" />
            </inertial>
        </link>

        <joint name="wheel_left_joint" type="continuous">
            <parent link="base_link"/>
            <child link="wheel_left_link"/>
            <origin xyz="0.00 ${0.23/2} 0.0250" rpy="${-M_PI/2} 0 0"/>
            <axis xyz="0 0 1"/>
        </joint>
        <link name="wheel_left_link">
            <visual>
                <geometry>
                    <mesh filename="$(find kobuki_gazebo)/meshes/kobuki_robot/meshes/wheel.dae"/>
                </geometry>
                <origin xyz="0 0 0" rpy="0 0 0"/>
            </visual>
            <collision>
                <geometry>
                <cylinder length="0.0206" radius="0.0352"/>
                </geometry>
                <origin rpy="0 0 0" xyz="0 0 0"/>
            </collision>
            <inertial>
                <mass value="0.01" />
                <origin xyz="0 0 0" />
                <inertia ixx="0.001" ixy="0.0" ixz="0.0"
                        iyy="0.001" iyz="0.0"
                        izz="0.001" />
            </inertial>
        </link>

        <joint name="wheel_right_joint" type="continuous">
            <parent link="base_link"/>
            <child link="wheel_right_link"/>
            <origin xyz="0.00 -${0.23/2} 0.0250" rpy="${-M_PI/2} 0 0"/>
            <axis xyz="0 0 1"/>
        </joint>
        <link name="wheel_right_link">
            <visual>
                <geometry>
                    <mesh filename="$(find kobuki_gazebo)/meshes/kobuki_robot/meshes/wheel.dae"/>
                </geometry>
                <origin xyz="0 0 0" rpy="0 0 0"/>
            </visual>
            <collision>
                <geometry>
                <cylinder length="0.0206" radius="0.0350"/>
                </geometry>
                <origin rpy="0 0 0" xyz="0 0 0"/>
            </collision>
            <inertial>
                <mass value="0.01" />
                <origin xyz="0 0 0" />
                <inertia ixx="0.001" ixy="0.0" ixz="0.0"
                        iyy="0.001" iyz="0.0"
                        izz="0.001" />
            </inertial>
        </link>

        <joint name="caster_front_joint" type="fixed">
            <parent link="base_link"/>
            <child link="caster_front_link"/>
            <origin xyz="0.115 0.0 0.007" rpy="${-M_PI/2} 0 0"/>
        </joint>
        <link name="caster_front_link">
            <collision>
                <geometry>
                <cylinder length="0.0176" radius="0.017"/>
                </geometry>
                <origin rpy="0 0 0" xyz="0 0 0"/>
            </collision>
            <inertial>
                <mass value="0.01" />
                <origin xyz="0 0 0" />
                <inertia ixx="0.001" ixy="0.0" ixz="0.0"
                        iyy="0.001" iyz="0.0"
                        izz="0.001" />
            </inertial>
        </link>

        <joint name="caster_back_joint" type="fixed">
            <parent link="base_link"/>
            <child link="caster_back_link"/>
            <origin xyz="-0.135 0.0 0.009" rpy="${-M_PI/2} 0 0"/>
        </joint>
        <link name="caster_back_link">
            <collision>
                <geometry>
                <cylinder length="0.0176" radius="0.017"/>
                </geometry>
                <origin rpy="0 0 0" xyz="0 0 0"/>
            </collision>
            <inertial>
                <mass value="0.01" />
                <origin xyz="0 0 0" />
                <inertia ixx="0.001" ixy="0.0" ixz="0.0"
                        iyy="0.001" iyz="0.0"
                        izz="0.001" />
            </inertial>
        </link>

        <!-- Kobuki's sensors -->
        <joint name="gyro_joint" type="fixed">
            <axis xyz="0 1 0"/>
            <origin xyz="0.056 0.062 0.0202" rpy="0 0 0"/>
            <parent link="base_link"/>
            <child link="gyro_link"/>
        </joint>
        <link name="gyro_link">
            <inertial>
                <mass value="0.001"/>
                <origin xyz="0 0 0" rpy="0 0 0"/>
                <inertia ixx="0.0001" ixy="0" ixz="0"
                        iyy="0.000001" iyz="0"
                        izz="0.0001"/>
            </inertial>
        </link>

        <joint name="cliff_sensor_left_joint" type="fixed">
            <origin xyz="0.08734 0.13601 0.0214" rpy="0 ${M_PI/2} 0" />
            <parent link="base_link"/>
            <child link="cliff_sensor_left_link" />
        </joint>
        <link name="cliff_sensor_left_link">
            <inertial>
                <mass value="0.0001" />
                <origin xyz="0 0 0" />
                <inertia ixx="0.0001" ixy="0.0" ixz="0.0"
                        iyy="0.0001" iyz="0.0"
                        izz="0.0001" />
            </inertial>
        </link>

        <joint name="cliff_sensor_right_joint" type="fixed">
            <origin xyz="0.085 -0.13601 0.0214" rpy="0 ${M_PI/2} 0" />
            <parent link="base_link"/>
            <child link="cliff_sensor_right_link" />
        </joint>
        <link name="cliff_sensor_right_link">
            <inertial>
                <mass value="0.0001" />
                <origin xyz="0 0 0" />
                <inertia ixx="0.0001" ixy="0.0" ixz="0.0"
                        iyy="0.0001" iyz="0.0"
                        izz="0.0001" />
            </inertial>
        </link>

        <joint name="cliff_sensor_front_joint" type="fixed">
            <origin xyz="0.156 0.00 0.0214" rpy="0 ${M_PI/2} 0" />
            <parent link="base_link"/>
            <child link="cliff_sensor_front_link" />
        </joint>
        <link name="cliff_sensor_front_link">
            <inertial>
                <mass value="0.0001" />
                <origin xyz="0 0 0" />
                <inertia ixx="0.0001" ixy="0.0" ixz="0.0"
                        iyy="0.0001" iyz="0.0"
                        izz="0.0001" />
            </inertial>
        </link>

        <!-- Kobuki Gazebo simulation details -->
        <gazebo reference="wheel_left_link">
            <mu1>1.0</mu1>
            <mu2>1.0</mu2>
            <kp>1000000.0</kp>
            <kd>100.0</kd>
            <minDepth>0.001</minDepth>
            <maxVel>1.0</maxVel>
        </gazebo>

        <gazebo reference="wheel_right_link">
            <mu1>1.0</mu1>
            <mu2>1.0</mu2>
            <kp>1000000.0</kp>
            <kd>100.0</kd>
            <minDepth>0.001</minDepth>
            <maxVel>1.0</maxVel>
        </gazebo>

        <gazebo reference="caster_front_link">
            <mu1>0.0</mu1>
            <mu2>0.0</mu2>
            <kp>1000000.0</kp>
            <kd>100.0</kd>
            <minDepth>0.001</minDepth>
            <maxVel>1.0</maxVel>
        </gazebo>

        <gazebo reference="caster_back_link">
            <mu1>0.0</mu1>
            <mu2>0.0</mu2>
            <kp>1000000.0</kp>
            <kd>100.0</kd>
            <minDepth>0.001</minDepth>
            <maxVel>1.0</maxVel>
        </gazebo>

        <gazebo reference="base_link">
            <mu1>0.3</mu1>
            <mu2>0.3</mu2>
            <sensor type="contact" name="bumpers">
                <always_on>true</always_on>
                <update_rate>50.0</update_rate>
                <visualize>true</visualize>
                <contact>
                    <collision>base_footprint_fixed_joint_lump__base_collision</collision>
                </contact>
                <plugin name="bumper_plugin" filename="libgazebo_ros_bumper.so">
                    <bumperTopicName>contact_state</bumperTopicName>
                </plugin>
            </sensor>
        </gazebo>

        <gazebo reference="cliff_sensor_left_link">
            <sensor type="ray" name="cliff_sensor_left">
                <always_on>true</always_on>
                <update_rate>50</update_rate>
                <visualize>true</visualize>
                <ray>
                    <scan>
                        <horizontal>
                            <samples>50</samples>
                            <resolution>1.0</resolution>
                            <min_angle>-0.0436</min_angle>  <!-- -2.5 degree -->
                            <max_angle>0.0436</max_angle> <!-- 2.5 degree -->
                        </horizontal>
                    </scan>
                    <range>
                        <min>0.01</min>
                        <max>0.15</max>
                        <resolution>1.0</resolution>
                    </range>
                </ray>
            </sensor>
        </gazebo>

        <gazebo reference="cliff_sensor_right_link">
            <sensor type="ray" name="cliff_sensor_right">
                <always_on>true</always_on>
                <update_rate>50</update_rate>
                <visualize>true</visualize>
                <ray>
                    <scan>
                        <horizontal>
                            <samples>50</samples>
                            <resolution>1.0</resolution>
                            <min_angle>-0.0436</min_angle>  <!-- -2.5 degree -->
                            <max_angle>0.0436</max_angle> <!-- 2.5 degree -->
                        </horizontal>
                    </scan>
                    <range>
                        <min>0.01</min>
                        <max>0.15</max>
                        <resolution>1.0</resolution>
                    </range>
                </ray>
            </sensor>
        </gazebo>

        <gazebo reference="cliff_sensor_front_link">
            <sensor type="ray" name="cliff_sensor_front">
                <always_on>true</always_on>
                <update_rate>50</update_rate>
                <visualize>true</visualize>
                <ray>
                    <scan>
                        <horizontal>
                            <samples>50</samples>
                            <resolution>1.0</resolution>
                            <min_angle>-0.0436</min_angle>  <!-- -2.5 degree -->
                            <max_angle>0.0436</max_angle> <!-- 2.5 degree -->
                        </horizontal>
                    </scan>
                    <range>
                        <min>0.01</min>
                        <max>0.15</max>
                        <resolution>1.0</resolution>
                    </range>
                </ray>
            </sensor>
        </gazebo>

        <gazebo reference="gyro_link">
            <sensor type="imu" name="imu">
                <always_on>true</always_on>
                <update_rate>50</update_rate>
                <visualize>false</visualize>
                <imu>
                    <noise>
                        <type>gaussian</type>
                        <rate>
                            <mean>0.0</mean>
                            <stddev>${0.0014*0.0014}</stddev> <!-- 0.25 x 0.25 (deg/s) -->
                            <bias_mean>0.0</bias_mean>
                            <bias_stddev>0.0</bias_stddev>
                        </rate>
                            <accel> <!-- not used in the plugin and real robot, hence using tutorial values -->
                                <mean>0.0</mean>
                                <stddev>1.7e-2</stddev>
                                <bias_mean>0.1</bias_mean>
                                <bias_stddev>0.001</bias_stddev>
                            </accel>
                    </noise>
                </imu>
            </sensor>
        </gazebo>

        <gazebo>
            <plugin name="kobuki_controller" filename="libgazebo_ros_kobuki.so">
                <publish_tf>1</publish_tf>
                <left_wheel_joint_name>wheel_left_joint</left_wheel_joint_name>
                <right_wheel_joint_name>wheel_right_joint</right_wheel_joint_name>
                <wheel_separation>.230</wheel_separation>
                <wheel_diameter>0.070</wheel_diameter>
                <torque>1.0</torque>
                <velocity_command_timeout>0.6</velocity_command_timeout>
                <cliff_sensor_left_name>cliff_sensor_left</cliff_sensor_left_name>
                <cliff_sensor_center_name>cliff_sensor_front</cliff_sensor_center_name>
                <cliff_sensor_right_name>cliff_sensor_right</cliff_sensor_right_name>
                <cliff_detection_threshold>0.04</cliff_detection_threshold>
                <bumper_name>bumpers</bumper_name>
                <imu_name>imu</imu_name>
            </plugin>
        </gazebo>

        <gazebo>
            <plugin name="differential_drive_controller"  filename="libgazebo_ros_diff_drive.so">
                <alwaysOn>true</alwaysOn>
                <publishWheelTF>true</publishWheelTF>
                <rosDebugLevel>Debug</rosDebugLevel>
                <robotNamespace>/</robotNamespace>
                <publishTf>1</publishTf>
                <publishWheelJointState>true</publishWheelJointState>
                <alwaysOn>true</alwaysOn>
                <updateRate>100.0</updateRate>
                <legacyMode>true</legacyMode>
                <leftJoint>wheel_left_joint</leftJoint>
                <rightJoint>wheel_right_joint</rightJoint>
                <wheelSeparation>.230</wheelSeparation>
                <wheelDiameter>0.070</wheelDiameter>
                <broadcastTF>0.1</broadcastTF>
                <wheelTorque>1</wheelTorque>
                <wheelAcceleration>1</wheelAcceleration>
                <commandTopic>/kabuki/cmd_vel</commandTopic>
                <odometryFrame>odom</odometryFrame> 
                <odometryTopic>/kabuki/odom</odometryTopic> 
                <robotBaseFrame>base_link</robotBaseFrame>
                <publishOdomTF>true</publishOdomTF>
                <odometrySource>world</odometrySource>
            </plugin>
        </gazebo>
    </xacro:macro>
</robot>


