<?xml version="1.0" ?>
<!-- =================================================================================== -->
<!-- |    This document was autogenerated by xacro from agv_with_sensors.urdf.xacro    | -->
<!-- |    EDITING THIS FILE BY HAND IS NOT RECOMMENDED                                 | -->
<!-- =================================================================================== -->
<robot name="arm">
  <!--
                                                                                     wheel_right_position                                               
                wheel_front_position                               body_position                          wheel_rear_position
                                                                                     wheel_left_position                                                 
    -->
  <!-- Defining the colors used in this robot -->
  <material name="yellow">
    <color rgba="1 0.4 0 1"/>
  </material>
  <material name="black">
    <color rgba="0 0 0 0.95"/>
  </material>
  <material name="gray">
    <color rgba="0.75 0.75 0.75 1"/>
  </material>
  <material name="white">
    <color rgba="1 1 1 1"/>
  </material>
  <material name="orange">
    <color rgba="1 0.27 0 1"/>
  </material>
  <link name="body_footprint">
    <visual>
      <origin rpy="0 0 0" xyz="0 0 0"/>
      <geometry>
        <box size="0.001 0.001 0.001"/>
      </geometry>
    </visual>
  </link>
  <gazebo reference="body_footprint">
    <turnGravityOff>false</turnGravityOff>
  </gazebo>
  <!-- body joint -->
  <joint name="body_footprint_joint" type="fixed">
    <origin rpy="0 0 0" xyz="0 0 0.07"/>
    <parent link="body_footprint"/>
    <child link="base_link"/>
  </joint>
  <!-- body -->
  <link name="base_link">
    <collision name="base_collision">
      <pose>0 0 0 0 0 0</pose>
      <geometry>
        <mesh filename="/home/lkq/ros_project/acc/0621/gazebo_ws/src/diff_gazebo/meshes/agv_robot/meshes/car_dae/car.dae"/>
      </geometry>
    </collision>
    <visual name="base_visual">
      <pose>0 0 0 0 0 0</pose>
      <geometry>
        <mesh filename="/home/lkq/ros_project/acc/0621/gazebo_ws/src/diff_gazebo/meshes/agv_robot/meshes/car_dae/car.dae"/>
      </geometry>
    </visual>
    <inertial>
      <mass value="10"/>
      <inertia ixx="0.6083333333333334" ixy="0" ixz="0" iyy="1.1354166666666667" iyz="0" izz="0.6770833333333331"/>
    </inertial>
    <!-- <sensor name='contacts' type='contact'>
                <contact>
                    <collision>base_collision</collision>
                </contact>
                <plugin name="gazebo_ros_bumper_controller" filename="libgazebo_ros_bumper.so">
                    <alwaysOn>true</alwaysOn>
                    <updateRate>20</updateRate>
                    <bumperTopicName>bumper</bumperTopicName>
                    <frameName>base_link</frameName>
                </plugin>
            </sensor> -->
  </link>
  <joint name="wheel_front_wheel_fun_1" type="continuous">
    <origin rpy="0 0  0" xyz="-0.3  0 -0.1625"/>
    <parent link="base_link"/>
    <child link="wheel_front_wheel_box_1_link"/>
    <axis xyz="0 0 1"/>
    <joint_properties damping="0.0" friction="10.0"/>
  </joint>
  <link name="wheel_front_wheel_box_1_link">
    <visual>
      <origin rpy="0 0 0" xyz=" 0 0 0"/>
      <geometry>
        <box size="0.02 0.02 0.02"/>
      </geometry>
    </visual>
    <inertial>
      <mass value="0.1"/>
      <inertia ixx="0.00016666666666666672" ixy="0" ixz="0" iyy="0.00016666666666666672" iyz="0" izz="0.00016666666666666672"/>
    </inertial>
  </link>
  <joint name="wheel_front_wheel_fun_2" type="continuous">
    <origin rpy="0 0  0" xyz="0 0 0"/>
    <parent link="wheel_front_wheel_box_1_link"/>
    <child link="wheel_front_wheel_box_2_link"/>
    <axis xyz="0 1 0"/>
    <joint_properties damping="0.0" friction="10.0"/>
  </joint>
  <link name="wheel_front_wheel_box_2_link">
    <visual>
      <origin rpy="0 0 0" xyz=" 0 0 0"/>
      <geometry>
        <box size="0.05 0.05 0.05"/>
      </geometry>
    </visual>
    <inertial>
      <mass value="0.1"/>
      <inertia ixx="0.00016666666666666672" ixy="0" ixz="0" iyy="0.00016666666666666672" iyz="0" izz="0.00016666666666666672"/>
    </inertial>
  </link>
  <joint name="wheel_front_wheel_fun_3" type="continuous">
    <origin rpy="0 0  0" xyz="0 0 0"/>
    <parent link="wheel_front_wheel_box_2_link"/>
    <child link="wheel_front_wheel_box_3_link"/>
    <axis xyz="1 0 0"/>
    <joint_properties damping="0.0" friction="10.0"/>
  </joint>
  <link name="wheel_front_wheel_box_3_link">
    <collision name="collision">
      <geometry>
        <mesh filename="/home/lkq/ros_project/acc/0621/gazebo_ws/src/diff_gazebo/meshes/agv_robot/meshes/wheel/fun_wheel/fun_wheel.dae"/>
      </geometry>
    </collision>
    <visual name="visual">
      <geometry>
        <mesh filename="/home/lkq/ros_project/acc/0621/gazebo_ws/src/diff_gazebo/meshes/agv_robot/meshes/wheel/fun_wheel/fun_wheel.dae"/>
      </geometry>
    </visual>
    <inertial>
      <mass value="1"/>
      <inertia ixx="0.00625" ixy="0" ixz="0" iyy="0.00625" iyz="0" izz="0.00625"/>
    </inertial>
  </link>
  <joint name="wheel_rear_wheel_fun_1" type="continuous">
    <origin rpy="0 0  0" xyz="0.3  0 -0.1625"/>
    <parent link="base_link"/>
    <child link="wheel_rear_wheel_box_1_link"/>
    <axis xyz="0 0 1"/>
    <joint_properties damping="0.0" friction="10.0"/>
  </joint>
  <link name="wheel_rear_wheel_box_1_link">
    <visual>
      <origin rpy="0 0 0" xyz=" 0 0 0"/>
      <geometry>
        <box size="0.02 0.02 0.02"/>
      </geometry>
    </visual>
    <inertial>
      <mass value="0.1"/>
      <inertia ixx="0.00016666666666666672" ixy="0" ixz="0" iyy="0.00016666666666666672" iyz="0" izz="0.00016666666666666672"/>
    </inertial>
  </link>
  <joint name="wheel_rear_wheel_fun_2" type="continuous">
    <origin rpy="0 0  0" xyz="0 0 0"/>
    <parent link="wheel_rear_wheel_box_1_link"/>
    <child link="wheel_rear_wheel_box_2_link"/>
    <axis xyz="0 1 0"/>
    <joint_properties damping="0.0" friction="10.0"/>
  </joint>
  <link name="wheel_rear_wheel_box_2_link">
    <visual>
      <origin rpy="0 0 0" xyz=" 0 0 0"/>
      <geometry>
        <box size="0.05 0.05 0.05"/>
      </geometry>
    </visual>
    <inertial>
      <mass value="0.1"/>
      <inertia ixx="0.00016666666666666672" ixy="0" ixz="0" iyy="0.00016666666666666672" iyz="0" izz="0.00016666666666666672"/>
    </inertial>
  </link>
  <joint name="wheel_rear_wheel_fun_3" type="continuous">
    <origin rpy="0 0  0" xyz="0 0 0"/>
    <parent link="wheel_rear_wheel_box_2_link"/>
    <child link="wheel_rear_wheel_box_3_link"/>
    <axis xyz="1 0 0"/>
    <joint_properties damping="0.0" friction="10.0"/>
  </joint>
  <link name="wheel_rear_wheel_box_3_link">
    <collision name="collision">
      <geometry>
        <mesh filename="/home/lkq/ros_project/acc/0621/gazebo_ws/src/diff_gazebo/meshes/agv_robot/meshes/wheel/fun_wheel/fun_wheel.dae"/>
      </geometry>
    </collision>
    <visual name="visual">
      <geometry>
        <mesh filename="/home/lkq/ros_project/acc/0621/gazebo_ws/src/diff_gazebo/meshes/agv_robot/meshes/wheel/fun_wheel/fun_wheel.dae"/>
      </geometry>
    </visual>
    <inertial>
      <mass value="1"/>
      <inertia ixx="0.00625" ixy="0" ixz="0" iyy="0.00625" iyz="0" izz="0.00625"/>
    </inertial>
  </link>
  <joint name="wheel_left_wheel_odom" type="continuous">
    <origin rpy="0 0  0" xyz="0  -0.38 -0.1"/>
    <parent link="base_link"/>
    <child link="wheel_left_wheel_link"/>
    <axis xyz="0 -1 0"/>
    <joint_properties damping="0.0" friction="0.0"/>
  </joint>
  <link name="wheel_left_wheel_link">
    <collision name="collision">
      <geometry>
        <mesh filename="/home/lkq/ros_project/acc/0621/gazebo_ws/src/diff_gazebo/meshes/agv_robot/meshes/wheel/power_wheel/power_wheel.dae"/>
      </geometry>
    </collision>
    <visual name="visual">
      <geometry>
        <mesh filename="/home/lkq/ros_project/acc/0621/gazebo_ws/src/diff_gazebo/meshes/agv_robot/meshes/wheel/power_wheel/power_wheel.dae"/>
      </geometry>
    </visual>
    <inertial>
      <mass value="3"/>
      <inertia ixx="0.01261875" ixy="0" ixz="0" iyy="0.01261875" iyz="0" izz="0.0234375"/>
    </inertial>
  </link>
  <!-- <transmission name="${prefix}_wheel_trans">
            <type>transmission_interface/SimpleTransmission</type>
            <joint name="${prefix}_wheel_odom" >
                <hardwareInterface>hardware_interface/EffortJointInterface</hardwareInterface>
            </joint>
            <actuator name="${prefix}_wheel_link_motor">
                <hardwareInterface>hardware_interface/EffortJointInterface</hardwareInterface>
                <mechanicalReduction>1</mechanicalReduction>
            </actuator>
        </transmission> -->
  <joint name="wheel_right_wheel_odom" type="continuous">
    <origin rpy="0 0  0" xyz="0  0.38 -0.1"/>
    <parent link="base_link"/>
    <child link="wheel_right_wheel_link"/>
    <axis xyz="0 -1 0"/>
    <joint_properties damping="0.0" friction="0.0"/>
  </joint>
  <link name="wheel_right_wheel_link">
    <collision name="collision">
      <geometry>
        <mesh filename="/home/lkq/ros_project/acc/0621/gazebo_ws/src/diff_gazebo/meshes/agv_robot/meshes/wheel/power_wheel/power_wheel.dae"/>
      </geometry>
    </collision>
    <visual name="visual">
      <geometry>
        <mesh filename="/home/lkq/ros_project/acc/0621/gazebo_ws/src/diff_gazebo/meshes/agv_robot/meshes/wheel/power_wheel/power_wheel.dae"/>
      </geometry>
    </visual>
    <inertial>
      <mass value="3"/>
      <inertia ixx="0.01261875" ixy="0" ixz="0" iyy="0.01261875" iyz="0" izz="0.0234375"/>
    </inertial>
  </link>
  <!-- <transmission name="${prefix}_wheel_trans">
            <type>transmission_interface/SimpleTransmission</type>
            <joint name="${prefix}_wheel_odom" >
                <hardwareInterface>hardware_interface/EffortJointInterface</hardwareInterface>
            </joint>
            <actuator name="${prefix}_wheel_link_motor">
                <hardwareInterface>hardware_interface/EffortJointInterface</hardwareInterface>
                <mechanicalReduction>1</mechanicalReduction>
            </actuator>
        </transmission> -->
  <gazebo>
    <plugin filename="libgazebo_ros_diff_drive.so" name="differential_drive_controller">
      <alwaysOn>true</alwaysOn>
      <publishWheelTF>true</publishWheelTF>
      <rosDebugLevel>Debug</rosDebugLevel>
      <robotNamespace>/</robotNamespace>
      <publishTf>1</publishTf>
      <publishWheelJointState>true</publishWheelJointState>
      <alwaysOn>true</alwaysOn>
      <updateRate>100.0</updateRate>
      <legacyMode>true</legacyMode>
      <leftJoint>wheel_left_wheel_odom</leftJoint>
      <rightJoint>wheel_right_wheel_odom</rightJoint>
      <wheelSeparation>0.76</wheelSeparation>
      <wheelDiameter>0.25</wheelDiameter>
      <broadcastTF>0.1</broadcastTF>
      <wheelTorque>1</wheelTorque>
      <wheelAcceleration>1</wheelAcceleration>
      <commandTopic>car/cmd_vel</commandTopic>
      <odometryFrame>odom</odometryFrame>
      <odometryTopic>car/odom</odometryTopic>
      <robotBaseFrame>base_link</robotBaseFrame>
      <publishOdomTF>true</publishOdomTF>
      <odometrySource>world</odometrySource>
    </plugin>
  </gazebo>
  <gazebo reference="base_link">
    <sensor name="contacts" type="contact">
      <contact>
        <collision>body_footprint_fixed_joint_lump__base_collision_collision_1</collision>
      </contact>
      <plugin filename="libgazebo_ros_bumper.so" name="gazebo_ros_bumper_controller">
        <always_on>true</always_on>
        <robotNamespace>/</robotNamespace>
        <bumperTopicName>car/bumper_states</bumperTopicName>
        <frameName>bumper</frameName>
        <visualize>true</visualize>
        <update_rate>50.0</update_rate>
      </plugin>
    </sensor>
    <material>Gazebo/Red</material>
    <mu1>0.1</mu1>
    <mu2>0.1</mu2>
    <gravity>true</gravity>
    <selfCollide>false</selfCollide>
  </gazebo>
  <!-- Create kinect reference frame -->
  <!-- Add mesh for kinect -->
  <link name="camera_link">
    <origin rpy="0 0 0" xyz="0 0 0"/>
    <visual>
      <origin rpy="1.570796 0 1.570796" xyz="0.0115 0 0.0100"/>
      <geometry>
        <mesh filename="package://realsense2_description/meshes/d415.stl"/>
      </geometry>
      <material name="white"/>
    </visual>
    <collision>
      <geometry>
        <box size="0.001 0.001 0.001"/>
      </geometry>
    </collision>
  </link>
  <joint name="camera_optical_joint" type="fixed">
    <origin rpy="-1.5708 0 -1.5708" xyz="0 0 0"/>
    <parent link="camera_link"/>
    <child link="camera_frame_optical"/>
  </joint>
  <link name="camera_frame_optical"/>
  <gazebo reference="camera_link">
    <sensor name="camera" type="depth">
      <always_on>true</always_on>
      <update_rate>50.0</update_rate>
      <camera>
        <horizontal_fov>1.57079632677</horizontal_fov>
        <image>
          <format>RGB8</format>
          <width>640</width>
          <height>480</height>
        </image>
        <clip>
          <near>0.05</near>
          <far>10000.0</far>
        </clip>
      </camera>
      <plugin filename="libgazebo_ros_openni_kinect.so" name="kinect_camera_controller">
        <cameraName>camera</cameraName>
        <alwaysOn>true</alwaysOn>
        <updateRate>50</updateRate>
        <imageTopicName>rgb/image_raw</imageTopicName>
        <depthImageTopicName>depth/image_raw</depthImageTopicName>
        <pointCloudTopicName>depth/points</pointCloudTopicName>
        <cameraInfoTopicName>rgb/camera_info</cameraInfoTopicName>
        <depthImageCameraInfoTopicName>depth/camera_info</depthImageCameraInfoTopicName>
        <frameName>camera_image</frameName>
        <baseline>0.1</baseline>
        <distortion_k1>0.0</distortion_k1>
        <distortion_k2>0.0</distortion_k2>
        <distortion_k3>0.0</distortion_k3>
        <distortion_t1>0.0</distortion_t1>
        <distortion_t2>0.0</distortion_t2>
        <pointCloudCutoff>0.4</pointCloudCutoff>
      </plugin>
    </sensor>
  </gazebo>
  <joint name="camera_joint" type="fixed">
    <origin rpy="0 0  3.1415926" xyz="-0.3 0 0.2"/>
    <parent link="base_link"/>
    <child link="camera_link"/>
    <axis xyz="1 0 0"/>
    <joint_properties damping="0.0" friction="10.0"/>
  </joint>
  <gazebo>
    <plugin filename="libgazebo_ros_control.so" name="gazebo_ros_control">
      <robotNamespace>/</robotNamespace>
      <controlPeriod>0.01</controlPeriod>
      <robotSimType>gazebo_ros_control/DefaultRobotHWSim</robotSimType>
    </plugin>
  </gazebo>
</robot>

